Workbook

Sheet 구간 표준
A1: 04 방산·우주·조선·해운 구간 표준 (국장·미장·일장 공통 순서)
A2: 종목 수는 '종목 목록' 시트에서 자동 집계("탭 밖 이동" 제외). 신규 종목은 종목 목록 시트에 파란색으로 표시.
A4: 순서 | B4: 표준 구간 | C4: 국장 | D4: 미장 | E4: 일장 | F4: 국장 종목 | G4: 미장 종목 | H4: 일장 종목
A5: 1 | B5: 방산 체계 | C5: =COUNTIFS('종목 목록'!$A$2:$A$89,"국장",'종목 목록'!$C$2:$C$89,$B5,'종목 목록'!$H$2:$H$89,"<>탭 밖 이동") -> 5 | D5: =COUNTIFS('종목 목록'!$A$2:$A$89,"미장",'종목 목록'!$C$2:$C$89,$B5,'종목 목록'!$H$2:$H$89,"<>탭 밖 이동") -> 5 | E5: =COUNTIFS('종목 목록'!$A$2:$A$89,"일장",'종목 목록'!$C$2:$C$89,$B5,'종목 목록'!$H$2:$H$89,"<>탭 밖 이동") -> 2 | F5: 한화시스템, 현대로템, LIG디펜스앤에어로스페이스, 풍산, 한화에어로스페이스 | G5: 록히드 마틴, 액손 엔터프라이즈, 제너럴 다이내믹스, 노스롭 그루만, L3 해리스 테크놀로지스 | H5: 미쓰비시 중공업, 가와사키중공업
A6: 2 | B6: 방산 부품 | C6: =COUNTIFS('종목 목록'!$A$2:$A$89,"국장",'종목 목록'!$C$2:$C$89,$B6,'종목 목록'!$H$2:$H$89,"<>탭 밖 이동") -> 2 | D6: =COUNTIFS('종목 목록'!$A$2:$A$89,"미장",'종목 목록'!$C$2:$C$89,$B6,'종목 목록'!$H$2:$H$89,"<>탭 밖 이동") -> 0 | E6: =COUNTIFS('종목 목록'!$A$2:$A$89,"일장",'종목 목록'!$C$2:$C$89,$B6,'종목 목록'!$H$2:$H$89,"<>탭 밖 이동") -> 6 | F6: 빅텍, 삼현 | G6: – | H6: 미쓰비시전기, 쿄세라, 하마마쓰포토닉스, 무라타 제작, TDK, 스미토모 전기
A7: 3 | B7: 항공 | C7: =COUNTIFS('종목 목록'!$A$2:$A$89,"국장",'종목 목록'!$C$2:$C$89,$B7,'종목 목록'!$H$2:$H$89,"<>탭 밖 이동") -> 3 | D7: =COUNTIFS('종목 목록'!$A$2:$A$89,"미장",'종목 목록'!$C$2:$C$89,$B7,'종목 목록'!$H$2:$H$89,"<>탭 밖 이동") -> 4 | E7: =COUNTIFS('종목 목록'!$A$2:$A$89,"일장",'종목 목록'!$C$2:$C$89,$B7,'종목 목록'!$H$2:$H$89,"<>탭 밖 이동") -> 1 | F7: 한국항공우주, 켄코아에어로스페이스, 아스트 | G7: 하우멧 에어로스페이스, GE에어로스페이스, 보잉, 트랜스다임 그룹 | H7: IHI
A8: 4 | B8: 우주 위성 | C8: =COUNTIFS('종목 목록'!$A$2:$A$89,"국장",'종목 목록'!$C$2:$C$89,$B8,'종목 목록'!$H$2:$H$89,"<>탭 밖 이동") -> 10 | D8: =COUNTIFS('종목 목록'!$A$2:$A$89,"미장",'종목 목록'!$C$2:$C$89,$B8,'종목 목록'!$H$2:$H$89,"<>탭 밖 이동") -> 4 | E8: =COUNTIFS('종목 목록'!$A$2:$A$89,"일장",'종목 목록'!$C$2:$C$89,$B8,'종목 목록'!$H$2:$H$89,"<>탭 밖 이동") -> 3 | F8: 이녹스첨단소재, 인텔리안테크, 스피어, 나라스페이스테크놀로지, 쎄트렉아이, 비츠로넥스텍, 에이치브이엠, AP위성, 나노팀, 와이제이링크 | G8: 로켓 랩, AST 스페이스모바일, 인튜이티브 머신스, 스페이스X | H8: ispace, QPS연구소, 아스트로스케일
A9: 5 | B9: 드론 | C9: =COUNTIFS('종목 목록'!$A$2:$A$89,"국장",'종목 목록'!$C$2:$C$89,$B9,'종목 목록'!$H$2:$H$89,"<>탭 밖 이동") -> 2 | D9: =COUNTIFS('종목 목록'!$A$2:$A$89,"미장",'종목 목록'!$C$2:$C$89,$B9,'종목 목록'!$H$2:$H$89,"<>탭 밖 이동") -> 4 | E9: =COUNTIFS('종목 목록'!$A$2:$A$89,"일장",'종목 목록'!$C$2:$C$89,$B9,'종목 목록'!$H$2:$H$89,"<>탭 밖 이동") -> 2 | F9: 퍼스텍, 제이씨현시스템 | G9: 에어로바이런먼트, 온다스, 레드 캣 홀딩스, 크라토스 디펜스 | H9: 테라드론, ACSL
A10: 6 | B10: 조선 | C10: =COUNTIFS('종목 목록'!$A$2:$A$89,"국장",'종목 목록'!$C$2:$C$89,$B10,'종목 목록'!$H$2:$H$89,"<>탭 밖 이동") -> 5 | D10: =COUNTIFS('종목 목록'!$A$2:$A$89,"미장",'종목 목록'!$C$2:$C$89,$B10,'종목 목록'!$H$2:$H$89,"<>탭 밖 이동") -> 1 | E10: =COUNTIFS('종목 목록'!$A$2:$A$89,"일장",'종목 목록'!$C$2:$C$89,$B10,'종목 목록'!$H$2:$H$89,"<>탭 밖 이동") -> 1 | F10: 한화오션, 대한조선, HD현대중공업, HD한국조선해양, 삼성중공업 | G10: 헌팅턴 잉걸스 인더스트리스 | H10: 나무라조선소
A11: 7 | B11: 조선기자재 | C11: =COUNTIFS('종목 목록'!$A$2:$A$89,"국장",'종목 목록'!$C$2:$C$89,$B11,'종목 목록'!$H$2:$H$89,"<>탭 밖 이동") -> 16 | D11: =COUNTIFS('종목 목록'!$A$2:$A$89,"미장",'종목 목록'!$C$2:$C$89,$B11,'종목 목록'!$H$2:$H$89,"<>탭 밖 이동") -> 0 | E11: =COUNTIFS('종목 목록'!$A$2:$A$89,"일장",'종목 목록'!$C$2:$C$89,$B11,'종목 목록'!$H$2:$H$89,"<>탭 밖 이동") -> 1 | F11: SK오션플랜트, 한화엔진, 케이프, 세진중공업, 현대힘스, 오리엔탈정공, HD현대마린엔진, 에스엔시스, 성광벤드, HD현대마린솔루션, 태웅, 한국카본, 티엠씨, 한라IMS, 동성화인텍, 태광 | G11: – | H11: 미쓰이이앤에스
A12: 8 | B12: 해운 | C12: =COUNTIFS('종목 목록'!$A$2:$A$89,"국장",'종목 목록'!$C$2:$C$89,$B12,'종목 목록'!$H$2:$H$89,"<>탭 밖 이동") -> 6 | D12: =COUNTIFS('종목 목록'!$A$2:$A$89,"미장",'종목 목록'!$C$2:$C$89,$B12,'종목 목록'!$H$2:$H$89,"<>탭 밖 이동") -> 2 | E12: =COUNTIFS('종목 목록'!$A$2:$A$89,"일장",'종목 목록'!$C$2:$C$89,$B12,'종목 목록'!$H$2:$H$89,"<>탭 밖 이동") -> 3 | F12: HMM, 대한해운, 팬오션, STX그린로지스, 흥아해운, KSS해운 | G12: 로빈 에너지, ZIM 인티그레이티드 시핑 | H12: 카와사키 기선, 미쓰이O.S.K.상선, 니혼유센
B13: 합계 | C13: =SUM(C5:C12) -> 49 | D13: =SUM(D5:D12) -> 20 | E13: =SUM(E5:E12) -> 19

Sheet 원래 그룹 정리
A1: 불러온 뒤 원래 그룹에서 빼야 할 종목
A3: 시장 | B3: 원래 위치 | C3: 종목명 | D3: 옮겨간 곳
A4: 국장 | B4: 주요테마 / 해운 | C4: HMM | D4: 04 방산·우주·조선 / 해운
A5: 국장 | B5: 주요테마 / 해운 | C5: 대한해운 | D5: 04 방산·우주·조선 / 해운
A6: 국장 | B6: 주요테마 / 해운 | C6: 팬오션 | D6: 04 방산·우주·조선 / 해운
A7: 국장 | B7: 주요테마 / 해운 | C7: STX그린로지스 | D7: 04 방산·우주·조선 / 해운
A8: 국장 | B8: 주요테마 / 해운 | C8: 흥아해운 | D8: 04 방산·우주·조선 / 해운
A9: 국장 | B9: 주요테마 / 해운 | C9: KSS해운 | D9: 04 방산·우주·조선 / 해운
A10: 미장 | B10: 미국 정책 수혜주 / 방위(ITA) | C10: 록히드 마틴 | D10: 04 방산·우주·조선 / 방산 체계
A11: 미장 | B11: 미국 정책 수혜주 / 방위(ITA) | C11: 액손 엔터프라이즈 | D11: 04 방산·우주·조선 / 방산 체계
A12: 미장 | B12: 미국 정책 수혜주 / 방위(ITA) | C12: 제너럴 다이내믹스 | D12: 04 방산·우주·조선 / 방산 체계
A13: 미장 | B13: 미국 정책 수혜주 / 방위(ITA) | C13: 노스롭 그루만 | D13: 04 방산·우주·조선 / 방산 체계
A14: 미장 | B14: 미국 정책 수혜주 / 방위(ITA) | C14: L3 해리스 테크놀로지스 | D14: 04 방산·우주·조선 / 방산 체계
... A35: 일장 | B35: 일본 섹터별 종목 / 해운 | C35: 미쓰이O.S.K.상선 | D35: 04 방산·우주·조선 / 해운

Sheet 확인 필요
A1: 결정이 필요한 항목
A3: 항목 | B3: 시장 | C3: 현재 처리 | D3: 검토 내용 | E3: 추천 | F3: 결정 (직접 입력)
A4: 이녹스첨단소재, 나노팀, 와이제이링크 | B4: 국장 | C4: 우주 위성 구간 유지 | D4: 본업이 소재·방열·장비라 우주 연관성 약함 | E4: 넣은 이유가 있으면 유지, 아니면 반도체 소재 탭으로
A5: 삼현 | B5: 국장 | C5: 방산 부품 (로봇 탭과 중복) | D5: 방산·로봇용 구동장치 | E5: 의도적 중복 유지
A6: 한화에어로스페이스 | B6: 국장 | C6: 우주항공 → 방산 체계 | D6: 매출 대부분 방산(K9·레드백)과 항공엔진 | E6: 방산 체계
A7: 액손 엔터프라이즈 | B7: 미장 | C7: 방산 체계 | D7: 치안 장비(테이저·바디캠), ITA ETF 편입 | E7: 유지 또는 제외
A8: 쿄세라, TDK, 무라타, 하마마쓰, 스미토모전기 | B8: 일장 | C8: 방산 부품 (원래 구간 유지) | D8: 일반 전자부품, 방산 매출 비중 작음 | E8: 미쓰비시전기만 남기고 정리해도 됨
A9: 해운 | B9: 3시장 | C9: 04 탭 맨 아래 해운 구간 | D9: 조선 수주와 운임 사이클 연결 | E9: 이 탭 유지
A10: 건설 | B10: 국장 | C10: 주요테마 탭에 그대로 | D10: 원전·플랜트 수주와 부동산 정책 두 갈래 | E10: 13 테마 / 건설 인프라 (미장 PAVE 인프라와 짝)
A11: 엔터 | B11: – | C11: 종목 없음 | D11: 콘텐츠 소비 | E11: 12 소비재 / 엔터 콘텐츠 구간 신설
A12: 일장 신규 10종목 코드 | B12: 일장 | C12: 추가 (코드 미검증) | D12: 가와사키중공업, IHI, ispace, QPS연구소, 아스트로스케일, 테라드론, ACSL, 나무라조선소, 미쓰이이앤에스, 니혼유센 | E12: 영웅문 Global에서 종목명 확인
A14: 빈칸메모 입력 순서 (세 시장 공통): 방산 체계 / 방산 부품 / 항공 / 우주 위성 / 드론 / 조선 / 조선기자재 / 해운 (미장은 방산 부품, 조선기자재 없음)

Sheet 종목 목록
A1: 시장 | B1: 구간 순서 | C1: 표준 구간 | D1: 원래 위치 (탭 / 구간) | E1: 종목명 | F1: 종목코드/티커 | G1: 영웅문 코드 | H1: 상태 | I1: 메모
A2: 국장 | B2: 1 | C2: 방산 체계 | D2: 방산 / 방산 | E2: 한화시스템 | F2: 272210 | G2: 272210 | H2: 유지 | I2: 레이더·전자전
A3: 국장 | B3: 1 | C3: 방산 체계 | D3: 방산 / 방산 | E3: 현대로템 | F3: 064350 | G3: 064350 | H3: 유지
A4: 국장 | B4: 1 | C4: 방산 체계 | D4: 방산 / 방산 | E4: LIG디펜스앤에어로스페이스 | F4: 079550 | G4: 079550 | H4: 유지
A5: 국장 | B5: 1 | C5: 방산 체계 | D5: 방산 / 방산 | E5: 풍산 | F5: 103140 | G5: 103140 | H5: 유지 | I5: 탄약, 구리 가공
A6: 국장 | B6: 1 | C6: 방산 체계 | D6: 방산 / 우주항공 | E6: 한화에어로스페이스 | F6: 012450 | G6: 012450 | H6: 구간 이동 | I6: K9 자주포·항공엔진, 록히드 짝
A7: 국장 | B7: 2 | C7: 방산 부품 | D7: 방산 / 방산 | E7: 빅텍 | F7: 065450 | G7: 065450 | H7: 구간 이동 | I7: 방산 전원장치
A8: 국장 | B8: 2 | C8: 방산 부품 | D8: 방산 / 방산 | E8: 삼현 | F8: 437730 | G8: 437730 | H8: 구간 이동 | I8: 로봇 탭과 중복
A9: 국장 | B9: 3 | C9: 항공 | D9: 방산 / 방산 | E9: 한국항공우주 | F9: 047810 | G9: 047810 | H9: 구간 이동 | I9: KF-21·FA-50, 보잉 짝
A10: 국장 | B10: 3 | C10: 항공 | D10: 방산 / 우주항공 | E10: 켄코아에어로스페이스 | F10: 274090 | G10: 274090 | H10: 구간 이동 | I10: 항공기 부품
A11: 국장 | B11: 3 | C11: 항공 | D11: 신규 / (신규) | E11: 아스트 | F11: 067390 | G11: 067390 | H11: 신규 | I11: 항공기 동체 부품, 보잉 납품
A12: 국장 | B12: 4 | C12: 우주 위성 | D12: 방산 / 우주항공 | E12: 이녹스첨단소재 | F12: 272290 | G12: 272290 | H12: 유지 | I12: 확인 필요: 본업과 우주 연관성
A13: 국장 | B13: 4 | C13: 우주 위성 | D13: 방산 / 우주항공 | E13: 인텔리안테크 | F13: 189300 | G13: 189300 | H13: 유지
A14: 국장 | B14: 4 | C14: 우주 위성 | D14: 방산 / 우주항공 | E14: 스피어 | F14: 347700 | G14: 347700 | H14: 유지
A15: 국장 | B15: 4 | C15: 우주 위성 | D15: 방산 / 우주항공 | E15: 나라스페이스테크놀로지 | F15: 478340 | G15: 478340 | H15: 유지
A16: 국장 | B16: 4 | C16: 우주 위성 | D16: 방산 / 우주항공 | E16: 쎄트렉아이 | F16: 099320 | G16: 099320 | H16: 유지
A17: 국장 | B17: 4 | C17: 우주 위성 | D17: 방산 / 우주항공 | E17: 비츠로넥스텍 | F17: 488900 | G17: 488900 | H17: 유지
A18: 국장 | B18: 4 | C18: 우주 위성 | D18: 방산 / 우주항공 | E18: 에이치브이엠 | F18: 295310 | G18: 295310 | H18: 유지
A19: 국장 | B19: 4 | C19: 우주 위성 | D19: 방산 / 우주항공 | E19: AP위성 | F19: 211270 | G19: 211270 | H19: 유지
A20: 국장 | B20: 4 | C20: 우주 위성 | D20: 방산 / 우주항공 | E20: 나노팀 | F20: 417010 | G20: 417010 | H20: 유지 | I20: 확인 필요: 본업과 우주 연관성
A21: 국장 | B21: 4 | C21: 우주 위성 | D21: 방산 / 우주항공 | E21: 와이제이링크 | F21: 209640 | G21: 209640 | H21: 유지 | I21: 확인 필요: 본업과 우주 연관성
A22: 국장 | B22: 5 | C22: 드론 | D22: 신규 / (신규) | E22: 퍼스텍 | F22: 010820 | G22: 010820 | H22: 신규 | I22: 유도무기 부품·드론
A23: 국장 | B23: 5 | C23: 드론 | D23: 신규 / (신규) | E23: 제이씨현시스템 | F23: 033320 | G23: 033320 | H23: 신규 | I23: 드론 유통
A24: 국장 | B24: 6 | C24: 조선 | D24: 방산 / 조선 | E24: 한화오션 | F24: 042660 | G24: 042660 | H24: 유지
A25: 국장 | B25: 6 | C25: 조선 | D25: 방산 / 조선 | E25: 대한조선 | F25: 439260 | G25: 439260 | H25: 유지
A26: 국장 | B26: 6 | C26: 조선 | D26: 방산 / 조선 | E26: HD현대중공업 | F26: 329180 | G26: 329180 | H26: 유지
A27: 국장 | B27: 6 | C27: 조선 | D27: 방산 / 조선 | E27: HD한국조선해양 | F27: 009540 | G27: 009540 | H27: 유지
A28: 국장 | B28: 6 | C28: 조선 | D28: 방산 / 조선 | E28: 삼성중공업 | F28: 010140 | G28: 010140 | H28: 유지
A29: 국장 | B29: 7 | C29: 조선기자재 | D29: 방산 / 조선기자재 | E29: SK오션플랜트 | F29: 100090 | G29: 100090 | H29: 유지
A30: 국장 | B30: 7 | C30: 조선기자재 | D30: 방산 / 조선기자재 | E30: 한화엔진 | F30: 082740 | G30: 082740 | H30: 유지
A31: 국장 | B31: 7 | C31: 조선기자재 | D31: 방산 / 조선기자재 | E31: 케이프 | F31: 064820 | G31: 064820 | H31: 유지
A32: 국장 | B32: 7 | C32: 조선기자재 | D32: 방산 / 조선기자재 | E32: 세진중공업 | F32: 075580 | G32: 075580 | H32: 유지
A33: 국장 | B33: 7 | C33: 조선기자재 | D33: 방산 / 조선기자재 | E33: 현대힘스 | F33: 460930 | G33: 460930 | H33: 유지
A34: 국장 | B34: 7 | C34: 조선기자재 | D34: 방산 / 조선기자재 | E34: 오리엔탈정공 | F34: 014940 | G34: 014940 | H34: 유지
A35: 국장 | B35: 7 | C35: 조선기자재 | D35: 방산 / 조선기자재 | E35: HD현대마린엔진 | F35: 071970 | G35: 071970 | H35: 유지
... A44: 국장 | B44: 7 | C44: 조선기자재 | D44: 방산 / 조선기자재 | E44: 태광 | F44: 023160 | G44: 023160 | H44: 유지
A45: 국장 | B45: 8 | C45: 해운 | D45: 주요테마 / 해운 | E45: HMM | F45: 011200 | G45: 011200 | H45: 추가 | I45: 주요테마 탭에서 이동, ZIM 짝
A46: 국장 | B46: 8 | C46: 해운 | D46: 주요테마 / 해운 | E46: 대한해운 | F46: 005880 | G46: 005880 | H46: 추가 | I46: 주요테마 탭에서 이동
A47: 국장 | B47: 8 | C47: 해운 | D47: 주요테마 / 해운 | E47: 팬오션 | F47: 028670 | G47: 028670 | H47: 추가 | I47: 주요테마 탭에서 이동
A48: 국장 | B48: 8 | C48: 해운 | D48: 주요테마 / 해운 | E48: STX그린로지스 | F48: 465770 | G48: 465770 | H48: 추가 | I48: 주요테마 탭에서 이동
...
