Workbook

Sheet 구간 표준
A1: 10 금융·핀테크 구간 표준 (국장·미장·일장 공통 순서)
A2: 종목 수는 '종목 목록' 시트에서 자동 집계("탭 밖 이동" 제외). 신규 종목은 종목 목록 시트에 파란색으로 표시.
A4: 순서 | B4: 표준 구간 | C4: 국장 | D4: 미장 | E4: 일장 | F4: 국장 종목 | G4: 미장 종목 | H4: 일장 종목
A5: 1 | B5: 은행 | C5: =COUNTIFS('종목 목록'!$A$2:$A$92,"국장",'종목 목록'!$C$2:$C$92,$B5,'종목 목록'!$H$2:$H$92,"<>탭 밖 이동") -> 11 | D5: =COUNTIFS('종목 목록'!$A$2:$A$92,"미장",'종목 목록'!$C$2:$C$92,$B5,'종목 목록'!$H$2:$H$92,"<>탭 밖 이동") -> 3 | E5: =COUNTIFS('종목 목록'!$A$2:$A$92,"일장",'종목 목록'!$C$2:$C$92,$B5,'종목 목록'!$H$2:$H$92,"<>탭 밖 이동") -> 3 | F5: KB금융, 우리금융지주, 메리츠금융지주, 기업은행, 하나금융지주, 카카오뱅크, 신한지주, BNK금융지주, 제주은행, JB금융지주, iM금융지주 | G5: 뱅크오브아메리카, 제이피모간 체이스, 웰스파고 | H5: 미쓰비시UFJ파이낸셜그룹, 미쓰이스미토모파이낸셜그룹, 미즈호파이낸셜그룹
A6: 2 | B6: 증권 | C6: =COUNTIFS('종목 목록'!$A$2:$A$92,"국장",'종목 목록'!$C$2:$C$92,$B6,'종목 목록'!$H$2:$H$92,"<>탭 밖 이동") -> 14 | D6: =COUNTIFS('종목 목록'!$A$2:$A$92,"미장",'종목 목록'!$C$2:$C$92,$B6,'종목 목록'!$H$2:$H$92,"<>탭 밖 이동") -> 3 | E6: =COUNTIFS('종목 목록'!$A$2:$A$92,"일장",'종목 목록'!$C$2:$C$92,$B6,'종목 목록'!$H$2:$H$92,"<>탭 밖 이동") -> 2 | F6: 미래에셋증권, 삼성증권, 키움증권, NH투자증권, 부국증권, 신영증권, 교보증권, 대신증권, DB증권, 유진투자증권, LS증권, 현대차증권, 한화투자증권, SK증권 | G6: 로빈후드, 찰스 슈왑, 골드만삭스 | H6: 노무라홀딩스, SBI홀딩스
A7: 3 | B7: 손해보험 | C7: =COUNTIFS('종목 목록'!$A$2:$A$92,"국장",'종목 목록'!$C$2:$C$92,$B7,'종목 목록'!$H$2:$H$92,"<>탭 밖 이동") -> 8 | D7: =COUNTIFS('종목 목록'!$A$2:$A$92,"미장",'종목 목록'!$C$2:$C$92,$B7,'종목 목록'!$H$2:$H$92,"<>탭 밖 이동") -> 1 | E7: =COUNTIFS('종목 목록'!$A$2:$A$92,"일장",'종목 목록'!$C$2:$C$92,$B7,'종목 목록'!$H$2:$H$92,"<>탭 밖 이동") -> 1 | F7: 한화손해보험, 흥국화재, 롯데손해보험, 현대해상, 삼성화재, DB손해보험, 서울보증보험, 코리안리 | G7: 처브 | H7: 도쿄해상홀딩스
A8: 4 | B8: 생명보험 | C8: =COUNTIFS('종목 목록'!$A$2:$A$92,"국장",'종목 목록'!$C$2:$C$92,$B8,'종목 목록'!$H$2:$H$92,"<>탭 밖 이동") -> 3 | D8: =COUNTIFS('종목 목록'!$A$2:$A$92,"미장",'종목 목록'!$C$2:$C$92,$B8,'종목 목록'!$H$2:$H$92,"<>탭 밖 이동") -> 1 | E8: =COUNTIFS('종목 목록'!$A$2:$A$92,"일장",'종목 목록'!$C$2:$C$92,$B8,'종목 목록'!$H$2:$H$92,"<>탭 밖 이동") -> 1 | F8: 한화생명, 삼성생명, 미래에셋생명 | G8: 메트라이프 | H8: 다이이치생명홀딩스
A9: 5 | B9: 결제 핀테크 | C9: =COUNTIFS('종목 목록'!$A$2:$A$92,"국장",'종목 목록'!$C$2:$C$92,$B9,'종목 목록'!$H$2:$H$92,"<>탭 밖 이동") -> 11 | D9: =COUNTIFS('종목 목록'!$A$2:$A$92,"미장",'종목 목록'!$C$2:$C$92,$B9,'종목 목록'!$H$2:$H$92,"<>탭 밖 이동") -> 4 | E9: =COUNTIFS('종목 목록'!$A$2:$A$92,"일장",'종목 목록'!$C$2:$C$92,$B9,'종목 목록'!$H$2:$H$92,"<>탭 밖 이동") -> 1 | F9: NHN KCP, 헥토파이낸셜, 아톤, 헥토이노베이션, 다날, 핑거, 쿠콘, 한국정보인증, 카카오페이, 더즌, 삼성카드 | G9: 마스타카드, 비자, 아메리칸 엑스프레스, 페이팔 홀딩스 | H9: GMO페이먼트게이트웨이
A10: 6 | B10: 디지털자산 | C10: =COUNTIFS('종목 목록'!$A$2:$A$92,"국장",'종목 목록'!$C$2:$C$92,$B10,'종목 목록'!$H$2:$H$92,"<>탭 밖 이동") -> 7 | D10: =COUNTIFS('종목 목록'!$A$2:$A$92,"미장",'종목 목록'!$C$2:$C$92,$B10,'종목 목록'!$H$2:$H$92,"<>탭 밖 이동") -> 3 | E10: =COUNTIFS('종목 목록'!$A$2:$A$92,"일장",'종목 목록'!$C$2:$C$92,$B10,'종목 목록'!$H$2:$H$92,"<>탭 밖 이동") -> 1 | F10: 한컴위드, 아이티센글로벌, 형지글로벌, LG씨엔에스, 미투온, 넥써쓰, 우리기술투자 | G10: 스트래티지, 코인베이스 글로벌, 써클 인터넷 그룹 | H10: 모넥스그룹
A11: 7 | B11: 자산운용 투자 | C11: =COUNTIFS('종목 목록'!$A$2:$A$92,"국장",'종목 목록'!$C$2:$C$92,$B11,'종목 목록'!$H$2:$H$92,"<>탭 밖 이동") -> 7 | D11: =COUNTIFS('종목 목록'!$A$2:$A$92,"미장",'종목 목록'!$C$2:$C$92,$B11,'종목 목록'!$H$2:$H$92,"<>탭 밖 이동") -> 3 | E11: =COUNTIFS('종목 목록'!$A$2:$A$92,"일장",'종목 목록'!$C$2:$C$92,$B11,'종목 목록'!$H$2:$H$92,"<>탭 밖 이동") -> 1 | F11: 아주IB투자, 미래에셋벤처투자, DSC인베스트먼트, TS인베스트먼트, 포바이포, 스톤브릿지벤처스, 에이티넘인베스트 | G11: 버크셔 해서웨이 B, 브룩필드, 블랙스톤 | H11: 오릭스
B12: 합계 | C12: =SUM(C5:C11) -> 61 | D12: =SUM(D5:D11) -> 18 | E12: =SUM(E5:E11) -> 10

Sheet 원래 그룹 정리
A1: 불러온 뒤 원래 그룹에서 빼야 할 종목
A3: 시장 | B3: 원래 위치 | C3: 종목명 | D3: 옮겨간 곳
A4: 국장 | B4: sw / 스테이블코인 | C4: NHN KCP | D4: 10 금융·핀테크 / 결제 핀테크
A5: 국장 | B5: sw / 스테이블코인 | C5: 헥토파이낸셜 | D5: 10 금융·핀테크 / 결제 핀테크
A6: 국장 | B6: sw / 스테이블코인 | C6: 아톤 | D6: 10 금융·핀테크 / 결제 핀테크
A7: 국장 | B7: sw / 스테이블코인 | C7: 헥토이노베이션 | D7: 10 금융·핀테크 / 결제 핀테크
A8: 국장 | B8: sw / 스테이블코인 | C8: 다날 | D8: 10 금융·핀테크 / 결제 핀테크
A9: 국장 | B9: sw / 스테이블코인 | C9: 핑거 | D9: 10 금융·핀테크 / 결제 핀테크
A10: 국장 | B10: sw / 스테이블코인 | C10: 쿠콘 | D10: 10 금융·핀테크 / 결제 핀테크
A11: 국장 | B11: sw / 스테이블코인 | C11: 한국정보인증 | D11: 10 금융·핀테크 / 결제 핀테크
A12: 국장 | B12: sw / 스테이블코인 | C12: 카카오페이 | D12: 10 금융·핀테크 / 결제 핀테크
A13: 국장 | B13: sw / 스테이블코인 | C13: 더즌 | D13: 10 금융·핀테크 / 결제 핀테크
A14: 국장 | B14: sw / 스테이블코인 | C14: 한컴위드 | D14: 10 금융·핀테크 / 디지털자산
... A23: 미장 | B23: 미국 에너지 / 풍력 | C23: 브룩필드 | D23: 10 금융·핀테크 / 자산운용 투자

Sheet 종목 목록
A1: 시장 | B1: 구간 순서 | C1: 표준 구간 | D1: 원래 위치 (탭 / 구간) | E1: 종목명 | F1: 종목코드/티커 | G1: 영웅문 코드 | H1: 상태 | I1: 메모
A2: 국장 | B2: 1 | C2: 은행 | D2: 금융 / 은행 | E2: KB금융 | F2: 105560 | G2: 105560 | H2: 유지
A3: 국장 | B3: 1 | C3: 은행 | D3: 금융 / 은행 | E3: 우리금융지주 | F3: 316140 | G3: 316140 | H3: 유지
A4: 국장 | B4: 1 | C4: 은행 | D4: 금융 / 은행 | E4: 메리츠금융지주 | F4: 138040 | G4: 138040 | H4: 유지 | I4: 보험·증권 중심 금융지주
A5: 국장 | B5: 1 | C5: 은행 | D5: 금융 / 은행 | E5: 기업은행 | F5: 024110 | G5: 024110 | H5: 유지
A6: 국장 | B6: 1 | C6: 은행 | D6: 금융 / 은행 | E6: 하나금융지주 | F6: 086790 | G6: 086790 | H6: 유지
A7: 국장 | B7: 1 | C7: 은행 | D7: 금융 / 은행 | E7: 카카오뱅크 | F7: 323410 | G7: 323410 | H7: 유지 | I7: 인터넷은행
A8: 국장 | B8: 1 | C8: 은행 | D8: 금융 / 은행 | E8: 신한지주 | F8: 055550 | G8: 055550 | H8: 유지
A9: 국장 | B9: 1 | C9: 은행 | D9: 금융 / 은행 | E9: BNK금융지주 | F9: 138930 | G9: 138930 | H9: 유지
A10: 국장 | B10: 1 | C10: 은행 | D10: 금융 / 은행 | E10: 제주은행 | F10: 006220 | G10: 006220 | H10: 유지
A11: 국장 | B11: 1 | C11: 은행 | D11: 금융 / 은행 | E11: JB금융지주 | F11: 175330 | G11: 175330 | H11: 유지
A12: 국장 | B12: 1 | C12: 은행 | D12: 금융 / 은행 | E12: iM금융지주 | F12: 139130 | G12: 139130 | H12: 유지
A13: 국장 | B13: 2 | C13: 증권 | D13: 금융 / 증권 | E13: 미래에셋증권 | F13: 006800 | G13: 006800 | H13: 유지
A14: 국장 | B14: 2 | C14: 증권 | D14: 금융 / 증권 | E14: 삼성증권 | F14: 016360 | G14: 016360 | H14: 유지
A15: 국장 | B15: 2 | C15: 증권 | D15: 금융 / 증권 | E15: 키움증권 | F15: 039490 | G15: 039490 | H15: 유지
A16: 국장 | B16: 2 | C16: 증권 | D16: 금융 / 증권 | E16: NH투자증권 | F16: 005940 | G16: 005940 | H16: 유지
A17: 국장 | B17: 2 | C17: 증권 | D17: 금융 / 증권 | E17: 부국증권 | F17: 001270 | G17: 001270 | H17: 유지
A18: 국장 | B18: 2 | C18: 증권 | D18: 금융 / 증권 | E18: 신영증권 | F18: 001720 | G18: 001720 | H18: 유지
A19: 국장 | B19: 2 | C19: 증권 | D19: 금융 / 증권 | E19: 교보증권 | F19: 030610 | G19: 030610 | H19: 유지
... A24: 국장 | B24: 2 | C24: 증권 | D24: 금융 / 증권 | E24: 현대차증권 | F24: 001500 | G24: 001500 | H24: 유지
A25: 국장 | B25: 2 | C25: 증권 | D25: 금융 / 증권 | E25: 한화투자증권 | F25: 003530 | G25: 003530 | H25: 유지 | I25: 두나무 지분 보유 (코인 연동)
A26: 국장 | B26: 2 | C26: 증권 | D26: 금융 / 증권 | E26: SK증권 | F26: 001510 | G26: 001510 | H26: 유지
A27: 국장 | B27: 3 | C27: 손해보험 | D27: 금융 / 보험 | E27: 한화손해보험 | F27: 000370 | G27: 000370 | H27: 유지
A28: 국장 | B28: 3 | C28: 손해보험 | D28: 금융 / 보험 | E28: 흥국화재 | F28: 000540 | G28: 000540 | H28: 유지
A29: 국장 | B29: 3 | C29: 손해보험 | D29: 금융 / 보험 | E29: 롯데손해보험 | F29: 000400 | G29: 000400 | H29: 유지
A30: 국장 | B30: 3 | C30: 손해보험 | D30: 금융 / 보험 | E30: 현대해상 | F30: 001450 | G30: 001450 | H30: 유지
A31: 국장 | B31: 3 | C31: 손해보험 | D31: 금융 / 보험 | E31: 삼성화재 | F31: 000810 | G31: 000810 | H31: 유지
A32: 국장 | B32: 3 | C32: 손해보험 | D32: 금융 / 보험 | E32: DB손해보험 | F32: 005830 | G32: 005830 | H32: 유지
A33: 국장 | B33: 3 | C33: 손해보험 | D33: 금융 / 보험 | E33: 서울보증보험 | F33: 031210 | G33: 031210 | H33: 유지 | I33: 보증보험
A34: 국장 | B34: 3 | C34: 손해보험 | D34: 금융 / 보험 | E34: 코리안리 | F34: 003690 | G34: 003690 | H34: 유지 | I34: 재보험
A35: 국장 | B35: 4 | C35: 생명보험 | D35: 금융 / 보험(생명) | E35: 한화생명 | F35: 088350 | G35: 088350 | H35: 유지
A36: 국장 | B36: 4 | C36: 생명보험 | D36: 금융 / 보험(생명) | E36: 삼성생명 | F36: 032830 | G36: 032830 | H36: 유지
A37: 국장 | B37: 4 | C37: 생명보험 | D37: 금융 / 보험(생명) | E37: 미래에셋생명 | F37: 085620 | G37: 085620 | H37: 유지
A38: 국장 | B38: 5 | C38: 결제 핀테크 | D38: sw / 스테이블코인 | E38: NHN KCP | F38: 060250 | G38: 060250 | H38: 추가 | I38: SW 탭 스테이블코인에서 이동
A39: 국장 | B39: 5 | C39: 결제 핀테크 | D39: sw / 스테이블코인 | E39: 헥토파이낸셜 | F39: 234340 | G39: 234340 | H39: 추가 | I39: SW 탭 스테이블코인에서 이동
A40: 국장 | B40: 5 | C40: 결제 핀테크 | D40: sw / 스테이블코인 | E40: 아톤 | F40: 158430 | G40: 158430 | H40: 추가 | I40: SW 탭 스테이블코인에서 이동
A41: 국장 | B41: 5 | C41: 결제 핀테크 | D41: sw / 스테이블코인 | E41: 헥토이노베이션 | F41: 214180 | G41: 214180 | H41: 추가 | I41: SW 탭 스테이블코인에서 이동
A42: 국장 | B42: 5 | C42: 결제 핀테크 | D42: sw / 스테이블코인 | E42: 다날 | F42: 064260 | G42: 064260 | H42: 추가 | I42: SW 탭 스테이블코인에서 이동
A43: 국장 | B43: 5 | C43: 결제 핀테크 | D43: sw / 스테이블코인 | E43: 핑거 | F43: 163730 | G43: 163730 | H43: 추가 | I43: SW 탭 스테이블코인에서 이동
A44: 국장 | B44: 5 | C44: 결제 핀테크 | D44: sw / 스테이블코인 | E44: 쿠콘 | F44: 294570 | G44: 294570 | H44: 추가 | I44: SW 탭 스테이블코인에서 이동
...
