Workbook

Sheet 구간 표준
A1: 반도체 구간 표준 (국장·미장·일장 공통 순서)
A2: 종목 수는 '종목 목록' 시트에서 자동 집계("탭 밖 이동" 제외). 종목명 열은 작성 시점 기준 텍스트.
A4: 순서 | B4: 표준 구간 | C4: 국장 탭 | D4: 국장 | E4: 미장 | F4: 일장 | G4: 국장 종목 | H4: 미장 종목 | I4: 일장 종목
A5: 1 | B5: 팹리스 | C5: 01 반도체 | D5: =COUNTIFS('종목 목록'!$A$2:$A$153,"국장",'종목 목록'!$D$2:$D$153,$B5,'종목 목록'!$I$2:$I$153,"<>탭 밖 이동") -> 7 | E5: =COUNTIFS('종목 목록'!$A$2:$A$153,"미장",'종목 목록'!$D$2:$D$153,$B5,'종목 목록'!$I$2:$I$153,"<>탭 밖 이동") -> 8 | F5: =COUNTIFS('종목 목록'!$A$2:$A$153,"일장",'종목 목록'!$D$2:$D$153,$B5,'종목 목록'!$I$2:$I$153,"<>탭 밖 이동") -> 0 | G5: 제주반도체, 칩스앤미디어, 엠디바이스, 파두, 사피엔반도체, 퀄리타스반도체, LX세미콘 | H5: 엔비디아, AMD, 에이알엠 홀딩스(ADR), 퀄컴, 시놉시스, 케이던스 디자인 시스템즈, 램버스, 세레브라스 시스템즈 | I5: –
A6: 2 | B6: ASIC 디자인하우스 | C6: 01 반도체 | D6: =COUNTIFS('종목 목록'!$A$2:$A$153,"국장",'종목 목록'!$D$2:$D$153,$B6,'종목 목록'!$I$2:$I$153,"<>탭 밖 이동") -> 5 | E6: =COUNTIFS('종목 목록'!$A$2:$A$153,"미장",'종목 목록'!$D$2:$D$153,$B6,'종목 목록'!$I$2:$I$153,"<>탭 밖 이동") -> 2 | F6: =COUNTIFS('종목 목록'!$A$2:$A$153,"일장",'종목 목록'!$D$2:$D$153,$B6,'종목 목록'!$I$2:$I$153,"<>탭 밖 이동") -> 1 | G6: 세미파이브, 가온칩스, 에이직랜드, 코아시아, 에이디테크놀로지 | H6: 브로드컴, 마벨 테크놀로지 그룹 | I6: 소시오넥스트
A7: 3 | B7: 메모리 | C7: 01 반도체 | D7: =COUNTIFS('종목 목록'!$A$2:$A$153,"국장",'종목 목록'!$D$2:$D$153,$B7,'종목 목록'!$I$2:$I$153,"<>탭 밖 이동") -> 3 | E7: =COUNTIFS('종목 목록'!$A$2:$A$153,"미장",'종목 목록'!$D$2:$D$153,$B7,'종목 목록'!$I$2:$I$153,"<>탭 밖 이동") -> 3 | F7: =COUNTIFS('종목 목록'!$A$2:$A$153,"일장",'종목 목록'!$D$2:$D$153,$B7,'종목 목록'!$I$2:$I$153,"<>탭 밖 이동") -> 1 | G7: 삼성전자, SK하이닉스, SK스퀘어 | H7: 마이크론 테크놀로지, 샌디스크, 웨스턴 디지털 | I7: 키오시아홀딩스
A8: 4 | B8: 반도체 유통 | C8: 01 반도체 | D8: =COUNTIFS('종목 목록'!$A$2:$A$153,"국장",'종목 목록'!$D$2:$D$153,$B8,'종목 목록'!$I$2:$I$153,"<>탭 밖 이동") -> 1 | E8: =COUNTIFS('종목 목록'!$A$2:$A$153,"미장",'종목 목록'!$D$2:$D$153,$B8,'종목 목록'!$I$2:$I$153,"<>탭 밖 이동") -> 0 | F8: =COUNTIFS('종목 목록'!$A$2:$A$153,"일장",'종목 목록'!$D$2:$D$153,$B8,'종목 목록'!$I$2:$I$153,"<>탭 밖 이동") -> 0 | G8: 미래반도체 | H8: – | I8: –
A9: 5 | B9: 파운드리 | C9: 01 반도체 | D9: =COUNTIFS('종목 목록'!$A$2:$A$153,"국장",'종목 목록'!$D$2:$D$153,$B9,'종목 목록'!$I$2:$I$153,"<>탭 밖 이동") -> 1 | E9: =COUNTIFS('종목 목록'!$A$2:$A$153,"미장",'종목 목록'!$D$2:$D$153,$B9,'종목 목록'!$I$2:$I$153,"<>탭 밖 이동") -> 4 | F9: =COUNTIFS('종목 목록'!$A$2:$A$153,"일장",'종목 목록'!$D$2:$D$153,$B9,'종목 목록'!$I$2:$I$153,"<>탭 밖 이동") -> 0 | G9: DB하이텍 | H9: TSMC(ADR), 글로벌파운드리스, 인텔, 유엠씨(ADS) | I9: –
A10: 6 | B10: 전공정 | C10: 01 반도체 | D10: =COUNTIFS('종목 목록'!$A$2:$A$153,"국장",'종목 목록'!$D$2:$D$153,$B10,'종목 목록'!$I$2:$I$153,"<>탭 밖 이동") -> 12 | E10: =COUNTIFS('종목 목록'!$A$2:$A$153,"미장",'종목 목록'!$D$2:$D$153,$B10,'종목 목록'!$I$2:$I$153,"<>탭 밖 이동") -> 4 | F10: =COUNTIFS('종목 목록'!$A$2:$A$153,"일장",'종목 목록'!$D$2:$D$153,$B10,'종목 목록'!$I$2:$I$153,"<>탭 밖 이동") -> 2 | G10: HPSP, 한화비전, 티에스이, 오로스테크놀로지, 원익IPS, 주성엔지니어링, 프로텍, 케이씨텍, 저스템, 그린리소스, 유니셈, 테스 | H10: ASML 홀딩(ADR), 램 리서치, 어플라이드 머티어리얼즈, 케이엘에이 | I10: 도쿄일렉트론, 알박
A11: 7 | B11: 후공정 | C11: 01 반도체 | D11: =COUNTIFS('종목 목록'!$A$2:$A$153,"국장",'종목 목록'!$D$2:$D$153,$B11,'종목 목록'!$I$2:$I$153,"<>탭 밖 이동") -> 12 | E11: =COUNTIFS('종목 목록'!$A$2:$A$153,"미장",'종목 목록'!$D$2:$D$153,$B11,'종목 목록'!$I$2:$I$153,"<>탭 밖 이동") -> 3 | F11: =COUNTIFS('종목 목록'!$A$2:$A$153,"일장",'종목 목록'!$D$2:$D$153,$B11,'종목 목록'!$I$2:$I$153,"<>탭 밖 이동") -> 4 | G11: 한미반도체, 고영, 피에스케이홀딩스, 제너셈, 이오테크닉스, 한빛레이저, 디아이, 비아트론, 네오셈, 와이씨, 엑시콘, 테크윙 | H11: 테라다인, 캠텍, 온투 이노베이션 | I11: 어드밴테스트, 디스코, 레이져테크, 하마마쓰포토닉스
A12: 8 | B12: OSAT | C12: 01 반도체 | D12: =COUNTIFS('종목 목록'!$A$2:$A$153,"국장",'종목 목록'!$D$2:$D$153,$B12,'종목 목록'!$I$2:$I$153,"<>탭 밖 이동") -> 5 | E12: =COUNTIFS('종목 목록'!$A$2:$A$153,"미장",'종목 목록'!$D$2:$D$153,$B12,'종목 목록'!$I$2:$I$153,"<>탭 밖 이동") -> 2 | F12: =COUNTIFS('종목 목록'!$A$2:$A$153,"일장",'종목 목록'!$D$2:$D$153,$B12,'종목 목록'!$I$2:$I$153,"<>탭 밖 이동") -> 0 | G12: 하나마이크론, 두산테스나, SFA반도체, 네패스, LB세미콘 | H12: ASE 테크놀로지 홀딩(ADR), 앰코 테크놀로지 | I12: –
A13: 9 | B13: 반도체소재 | C13: 01-2 반도체 소재·부품 | D13: =COUNTIFS('종목 목록'!$A$2:$A$153,"국장",'종목 목록'!$D$2:$D$153,$B13,'종목 목록'!$I$2:$I$153,"<>탭 밖 이동") -> 12 | E13: =COUNTIFS('종목 목록'!$A$2:$A$153,"미장",'종목 목록'!$D$2:$D$153,$B13,'종목 목록'!$I$2:$I$153,"<>탭 밖 이동") -> 2 | F13: =COUNTIFS('종목 목록'!$A$2:$A$153,"일장",'종목 목록'!$D$2:$D$153,$B13,'종목 목록'!$I$2:$I$153,"<>탭 밖 이동") -> 1 | G13: 리노공업, ISC, 비에이치, 서울반도체, 동진쎄미켐, 코미코, 티씨케이, 티에프이, 티이엠씨, 마이크로컨텍솔, 코스텍시스, 원익홀딩스 | H13: 큐니티 일렉트로닉스, 인테그리스 | I13: 아지노모토
A14: 10 | B14: 불화수소 | C14: 01-2 반도체 소재·부품 | D14: =COUNTIFS('종목 목록'!$A$2:$A$153,"국장",'종목 목록'!$D$2:$D$153,$B14,'종목 목록'!$I$2:$I$153,"<>탭 밖 이동") -> 4 | E14: =COUNTIFS('종목 목록'!$A$2:$A$153,"미장",'종목 목록'!$D$2:$D$153,$B14,'종목 목록'!$I$2:$I$153,"<>탭 밖 이동") -> 0 | F14: =COUNTIFS('종목 목록'!$A$2:$A$153,"일장",'종목 목록'!$D$2:$D$153,$B14,'종목 목록'!$I$2:$I$153,"<>탭 밖 이동") -> 1 | G14: 이엔에프테크놀로지, 솔브레인, 후성, 램테크놀러지 | H14: – | I14: 스텔라케미파
A15: 11 | B15: 웨이퍼 | C15: 01-2 반도체 소재·부품 | D15: =COUNTIFS('종목 목록'!$A$2:$A$153,"국장",'종목 목록'!$D$2:$D$153,$B15,'종목 목록'!$I$2:$I$153,"<>탭 밖 이동") -> 0 | E15: =COUNTIFS('종목 목록'!$A$2:$A$153,"미장",'종목 목록'!$D$2:$D$153,$B15,'종목 목록'!$I$2:$I$153,"<>탭 밖 이동") -> 0 | F15: =COUNTIFS('종목 목록'!$A$2:$A$153,"일장",'종목 목록'!$D$2:$D$153,$B15,'종목 목록'!$I$2:$I$153,"<>탭 밖 이동") -> 2 | G15: – | H15: – | I15: 섬코, 신에츠화학
A16: 12 | B16: 포토레지스트 | C16: 01-2 반도체 소재·부품 | D16: =COUNTIFS('종목 목록'!$A$2:$A$153,"국장",'종목 목록'!$D$2:$D$153,$B16,'종목 목록'!$I$2:$I$153,"<>탭 밖 이동") -> 0 | E16: =COUNTIFS('종목 목록'!$A$2:$A$153,"미장",'종목 목록'!$D$2:$D$153,$B16,'종목 목록'!$I$2:$I$153,"<>탭 밖 이동") -> 0 | F16: =COUNTIFS('종목 목록'!$A$2:$A$153,"일장",'종목 목록'!$D$2:$D$153,$B16,'종목 목록'!$I$2:$I$153,"<>탭 밖 이동") -> 2 | G16: – | H16: – | I16: 미쓰이화학, 도쿄응화공업
... A21: 17 | B21: MLCC | C21: 01-2 반도체 소재·부품 | D21: =COUNTIFS('종목 목록'!$A$2:$A$153,"국장",'종목 목록'!$D$2:$D$153,$B21,'종목 목록'!$I$2:$I$153,"<>탭 밖 이동") -> 5 | E21: =COUNTIFS('종목 목록'!$A$2:$A$153,"미장",'종목 목록'!$D$2:$D$153,$B21,'종목 목록'!$I$2:$I$153,"<>탭 밖 이동") -> 3 | F21: =COUNTIFS('종목 목록'!$A$2:$A$153,"일장",'종목 목록'!$D$2:$D$153,$B21,'종목 목록'!$I$2:$I$153,"<>탭 밖 이동") -> 2 | G21: 삼성전기, 삼화콘덴서, 아모텍, 한켐, 코칩 | H21: 비샤이 인터테크놀로지, 놀스, 로저스 | I21: 무라타 제작, 다이요유전
B22: 합계 | D22: =SUM(D5:D21) -> 84 | E22: =SUM(E5:E21) -> 41 | F22: =SUM(F5:F21) -> 26

Sheet 탭 요약
A1: 시장별 탭 구성
A3: 시장 | B3: 탭 | C3: 구간 범위 | D3: 종목 수 | E3: 제외 후보 | F3: 최종 예상 | G3: CSV 파일
A4: 국장 | B4: 01 반도체 | C4: 팹리스 ~ OSAT (1~8) | D4: =COUNTIFS('종목 목록'!$A$2:$A$151,$A4,'종목 목록'!$B$2:$B$151,$B4,'종목 목록'!$I$2:$I$151,"<>탭 밖 이동") -> 46 | E4: =COUNTIFS('종목 목록'!$A$2:$A$151,$A4,'종목 목록'!$B$2:$B$151,$B4,'종목 목록'!$I$2:$I$151,"제외 후보") -> 0 | F4: =D4-E4 -> 46 | G4: 국장_01 반도체.csv
A5: 국장 | B5: 01-2 반도체 소재·부품 | C5: 반도체소재 ~ MLCC (9~17) | D5: =COUNTIFS('종목 목록'!$A$2:$A$151,$A5,'종목 목록'!$B$2:$B$151,$B5,'종목 목록'!$I$2:$I$151,"<>탭 밖 이동") -> 38 | E5: =COUNTIFS('종목 목록'!$A$2:$A$151,$A5,'종목 목록'!$B$2:$B$151,$B5,'종목 목록'!$I$2:$I$151,"제외 후보") -> 2 | F5: =D5-E5 -> 36 | G5: 국장_01-2 반도체 소재_부품.csv
A6: 미장 | B6: 01 반도체 | C6: 전체 (1~17) | D6: =COUNTIFS('종목 목록'!$A$2:$A$151,$A6,'종목 목록'!$B$2:$B$151,$B6,'종목 목록'!$I$2:$I$151,"<>탭 밖 이동") -> 41 | E6: =COUNTIFS('종목 목록'!$A$2:$A$151,$A6,'종목 목록'!$B$2:$B$151,$B6,'종목 목록'!$I$2:$I$151,"제외 후보") -> 0 | F6: =D6-E6 -> 41 | G6: 미장_01 반도체.csv
A7: 일장 | B7: 01 반도체 | C7: 전체 (1~17) | D7: =COUNTIFS('종목 목록'!$A$2:$A$151,$A7,'종목 목록'!$B$2:$B$151,$B7,'종목 목록'!$I$2:$I$151,"<>탭 밖 이동") -> 24 | E7: =COUNTIFS('종목 목록'!$A$2:$A$151,$A7,'종목 목록'!$B$2:$B$151,$B7,'종목 목록'!$I$2:$I$151,"제외 후보") -> 0 | F7: =D7-E7 -> 24 | G7: 일장_01 반도체.csv
A10: 규칙
A11: • 표준화는 탭이 아니라 구간 이름과 순서 기준입니다. 종목이 없는 시장은 그 구간을 건너뜁니다.
A12: • 국장만 두 탭으로 나눕니다(OSAT | 반도체소재 경계). 미장·일장은 종목이 늘면 같은 경계에서 나눕니다.
A13: • DSP와 ASIC은 "ASIC 디자인하우스" 한 구간으로 합쳤습니다. 브로드컴·마벨 커스텀 ASIC ↔ 국장 디자인하우스 ↔ 소시오넥스트.
A14: • 불화수소 구간 신설: 솔브레인, 이엔에프테크놀로지, 램테크놀러지 ↔ 스텔라케미파.
A15: • 신규 추가 종목(코아시아, 에이디테크놀로지, 램테크놀러지, TTM 테크놀로지스)은 키움에서 종목코드를 확인했습니다.
A16: • 상태 색: 노랑=구간 이동, 초록=추가, 주황=제외 후보, 회색=탭 밖 이동 (종목 목록 시트).

Sheet 종목 목록
A1: 시장 | B1: 탭 | C1: 구간 순서 | D1: 표준 구간 | E1: 기존 구간(빈칸메모) | F1: 종목명 | G1: 종목코드/티커 | H1: 영웅문 코드 | I1: 상태 | J1: 메모
A2: 국장 | B2: 01 반도체 | C2: 1 | D2: 팹리스 | E2: 팹리스 | F2: 제주반도체 | G2: 080220 | H2: 080220 | I2: 유지
A3: 국장 | B3: 01 반도체 | C3: 1 | D3: 팹리스 | E3: 팹리스 | F3: 칩스앤미디어 | G3: 094360 | H3: 094360 | I3: 유지
A4: 국장 | B4: 01 반도체 | C4: 1 | D4: 팹리스 | E4: 팹리스 | F4: 엠디바이스 | G4: 226590 | H4: 226590 | I4: 유지
A5: 국장 | B5: 01 반도체 | C5: 1 | D5: 팹리스 | E5: 팹리스 | F5: 파두 | G5: 440110 | H5: 440110 | I5: 유지
A6: 국장 | B6: 01 반도체 | C6: 1 | D6: 팹리스 | E6: 팹리스 | F6: 사피엔반도체 | G6: 452430 | H6: 452430 | I6: 유지
A7: 국장 | B7: 01 반도체 | C7: 1 | D7: 팹리스 | E7: 팹리스 | F7: 퀄리타스반도체 | G7: 432720 | H7: 432720 | I7: 유지
A8: 국장 | B8: 01 반도체 | C8: 1 | D8: 팹리스 | E8: 팹리스 | F8: LX세미콘 | G8: 108320 | H8: 108320 | I8: 유지
A9: 국장 | B9: 01 반도체 | C9: 2 | D9: ASIC 디자인하우스 | E9: DSP(디자인하우스) | F9: 세미파이브 | G9: 490470 | H9: 490470 | I9: 유지
A10: 국장 | B10: 01 반도체 | C10: 2 | D10: ASIC 디자인하우스 | E10: 팹리스 | F10: 가온칩스 | G10: 399720 | H10: 399720 | I10: 구간 이동 | J10: 팹리스가 아니라 디자인하우스(DSP/VCA)
A11: 국장 | B11: 01 반도체 | C11: 2 | D11: ASIC 디자인하우스 | E11: 팹리스 | F11: 에이직랜드 | G11: 445090 | H11: 445090 | I11: 구간 이동 | J11: 팹리스가 아니라 디자인하우스(DSP/VCA)
A12: 국장 | B12: 01 반도체 | C12: 2 | D12: ASIC 디자인하우스 | E12: (신규) | F12: 코아시아 | G12: 045970 | H12: 045970 | I12: 추가 | J12: 삼성 파운드리 DSP, 신규 추가
A13: 국장 | B13: 01 반도체 | C13: 2 | D13: ASIC 디자인하우스 | E13: (신규) | F13: 에이디테크놀로지 | G13: 200710 | H13: 200710 | I13: 추가 | J13: 삼성 파운드리 DSP, 신규 추가
A14: 국장 | B14: 01 반도체 | C14: 3 | D14: 메모리 | E14: 메모리 | F14: 삼성전자 | G14: 005930 | H14: 005930 | I14: 유지
A15: 국장 | B15: 01 반도체 | C15: 3 | D15: 메모리 | E15: 메모리 | F15: SK하이닉스 | G15: 000660 | H15: 000660 | I15: 유지
A16: 국장 | B16: 01 반도체 | C16: 3 | D16: 메모리 | E16: 메모리 | F16: SK스퀘어 | G16: 402340 | H16: 402340 | I16: 유지
A17: 국장 | B17: 01 반도체 | C17: 4 | D17: 반도체 유통 | E17: 반도체 유통 | F17: 미래반도체 | G17: 254490 | H17: 254490 | I17: 유지
A18: 국장 | B18: 01 반도체 | C18: 5 | D18: 파운드리 | E18: 파운드리 | F18: DB하이텍 | G18: 000990 | H18: 000990 | I18: 유지
A19: 국장 | B19: 01 반도체 | C19: 6 | D19: 전공정 | E19: 전공정 | F19: HPSP | G19: 403870 | H19: 403870 | I19: 유지
A20: 국장 | B20: 01 반도체 | C20: 6 | D20: 전공정 | E20: 전공정 | F20: 한화비전 | G20: 489790 | H20: 489790 | I20: 유지
A21: 국장 | B21: 01 반도체 | C21: 6 | D21: 전공정 | E21: 전공정 | F21: 티에스이 | G21: 131290 | H21: 131290 | I21: 유지
A22: 국장 | B22: 01 반도체 | C22: 6 | D22: 전공정 | E22: 전공정 | F22: 오로스테크놀로지 | G22: 322310 | H22: 322310 | I22: 유지
A23: 국장 | B23: 01 반도체 | C23: 6 | D23: 전공정 | E23: 전공정 | F23: 원익IPS | G23: 240810 | H23: 240810 | I23: 유지
A24: 국장 | B24: 01 반도체 | C24: 6 | D24: 전공정 | E24: 전공정 | F24: 주성엔지니어링 | G24: 036930 | H24: 036930 | I24: 유지
A25: 국장 | B25: 01 반도체 | C25: 6 | D25: 전공정 | E25: 전공정 | F25: 프로텍 | G25: 053610 | H25: 053610 | I25: 유지
A26: 국장 | B26: 01 반도체 | C26: 6 | D26: 전공정 | E26: 전공정 | F26: 케이씨텍 | G26: 281820 | H26: 281820 | I26: 유지 | J26: 유리기판 관련주 (데이터센터 탭에서는 정리 예정)
A27: 국장 | B27: 01 반도체 | C27: 6 | D27: 전공정 | E27: 전공정 | F27: 저스템 | G27: 417840 | H27: 417840 | I27: 유지
A28: 국장 | B28: 01 반도체 | C28: 6 | D28: 전공정 | E28: 전공정 | F28: 그린리소스 | G28: 402490 | H28: 402490 | I28: 유지
A29: 국장 | B29: 01 반도체 | C29: 6 | D29: 전공정 | E29: 전공정 | F29: 유니셈 | G29: 036200 | H29: 036200 | I29: 유지
A30: 국장 | B30: 01 반도체 | C30: 6 | D30: 전공정 | E30: 전력/아날로그/차량용 반도체 | F30: 테스 | G30: 095610 | H30: 095610 | I30: 구간 이동 | J30: 증착장비 업체라 전공정으로 이동
A31: 국장 | B31: 01 반도체 | C31: 7 | D31: 후공정 | E31: 후공정 | F31: 한미반도체 | G31: 042700 | H31: 042700 | I31: 유지
A32: 국장 | B32: 01 반도체 | C32: 7 | D32: 후공정 | E32: 후공정 | F32: 고영 | G32: 098460 | H32: 098460 | I32: 유지
A33: 국장 | B33: 01 반도체 | C33: 7 | D33: 후공정 | E33: 후공정 | F33: 피에스케이홀딩스 | G33: 031980 | H33: 031980 | I33: 유지
A34: 국장 | B34: 01 반도체 | C34: 7 | D34: 후공정 | E34: 후공정 | F34: 제너셈 | G34: 217190 | H34: 217190 | I34: 유지
A35: 국장 | B35: 01 반도체 | C35: 7 | D35: 후공정 | E35: 후공정 | F35: 이오테크닉스 | G35: 039030 | H35: 039030 | I35: 유지
A36: 국장 | B36: 01 반도체 | C36: 7 | D36: 후공정 | E36: 후공정 | F36: 한빛레이저 | G36: 452190 | H36: 452190 | I36: 유지
A37: 국장 | B37: 01 반도체 | C37: 7 | D37: 후공정 | E37: 후공정 | F37: 디아이 | G37: 003160 | H37: 003160 | I37: 유지
A38: 국장 | B38: 01 반도체 | C38: 7 | D38: 후공정 | E38: 후공정 | F38: 비아트론 | G38: 141000 | H38: 141000 | I38: 유지 | J38: 유리기판 관련주 (데이터센터 탭에서는 정리 예정)
A39: 국장 | B39: 01 반도체 | C39: 7 | D39: 후공정 | E39: 후공정 | F39: 네오셈 | G39: 253590 | H39: 253590 | I39: 유지
A40: 국장 | B40: 01 반도체 | C40: 7 | D40: 후공정 | E40: 후공정 | F40: 와이씨 | G40: 232140 | H40: 232140 | I40: 유지 | J40: 유리기판 관련주 (데이터센터 탭에서는 정리 예정)
...
